{"timestamp": "2025-06-03T17:42:38.321058", "level": "ERROR", "logger": "server", "message": "Unhandled exception: ConnectionError: Database not connected. Call connect() first.", "module": "logging_config", "function": "log_with_context", "line": 119, "error_id": "4399211968", "error_type": "ConnectionError", "path": "/tasks", "method": "POST", "client": "testclient", "traceback": "Traceback (most recent call last):\n  File \"/Users/topiputih/Developments/company/sii/distributed-cracking/venv/lib/python3.11/site-packages/starlette/middleware/errors.py\", line 162, in __call__\n    await self.app(scope, receive, _send)\n  File \"/Users/topiputih/Developments/company/sii/distributed-cracking/venv/lib/python3.11/site-packages/starlette/middleware/cors.py\", line 83, in __call__\n    await self.app(scope, receive, send)\n  File \"/Users/topiputih/Developments/company/sii/distributed-cracking/venv/lib/python3.11/site-packages/starlette/middleware/exceptions.py\", line 79, in __call__\n    raise exc\n  File \"/Users/topiputih/Developments/company/sii/distributed-cracking/venv/lib/python3.11/site-packages/starlette/middleware/exceptions.py\", line 68, in __call__\n    await self.app(scope, receive, sender)\n  File \"/Users/topiputih/Developments/company/sii/distributed-cracking/venv/lib/python3.11/site-packages/fastapi/middleware/asyncexitstack.py\", line 20, in __call__\n    raise e\n  File \"/Users/topiputih/Developments/company/sii/distributed-cracking/venv/lib/python3.11/site-packages/fastapi/middleware/asyncexitstack.py\", line 17, in __call__\n    await self.app(scope, receive, send)\n  File \"/Users/topiputih/Developments/company/sii/distributed-cracking/venv/lib/python3.11/site-packages/starlette/routing.py\", line 718, in __call__\n    await route.handle(scope, receive, send)\n  File \"/Users/topiputih/Developments/company/sii/distributed-cracking/venv/lib/python3.11/site-packages/starlette/routing.py\", line 276, in handle\n    await self.app(scope, receive, send)\n  File \"/Users/topiputih/Developments/company/sii/distributed-cracking/venv/lib/python3.11/site-packages/starlette/routing.py\", line 66, in app\n    response = await func(request)\n               ^^^^^^^^^^^^^^^^^^^\n  File \"/Users/topiputih/Developments/company/sii/distributed-cracking/venv/lib/python3.11/site-packages/fastapi/routing.py\", line 264, in app\n    solved_result = await solve_dependencies(\n                    ^^^^^^^^^^^^^^^^^^^^^^^^^\n  File \"/Users/topiputih/Developments/company/sii/distributed-cracking/venv/lib/python3.11/site-packages/fastapi/dependencies/utils.py\", line 563, in solve_dependencies\n    solved_result = await solve_dependencies(\n                    ^^^^^^^^^^^^^^^^^^^^^^^^^\n  File \"/Users/topiputih/Developments/company/sii/distributed-cracking/venv/lib/python3.11/site-packages/fastapi/dependencies/utils.py\", line 563, in solve_dependencies\n    solved_result = await solve_dependencies(\n                    ^^^^^^^^^^^^^^^^^^^^^^^^^\n  File \"/Users/topiputih/Developments/company/sii/distributed-cracking/venv/lib/python3.11/site-packages/fastapi/dependencies/utils.py\", line 592, in solve_dependencies\n    solved = await call(**sub_values)\n             ^^^^^^^^^^^^^^^^^^^^^^^^\n  File \"/Users/topiputih/Developments/company/sii/distributed-cracking/cmd/server.py\", line 139, in get_db\n    db = Database.get_database()\n         ^^^^^^^^^^^^^^^^^^^^^^^\n  File \"/Users/topiputih/Developments/company/sii/distributed-cracking/config/database.py\", line 38, in get_database\n    raise ConnectionError(\"Database not connected. Call connect() first.\")\nConnectionError: Database not connected. Call connect() first.\n"}
{"timestamp": "2025-06-03T17:42:38.327663", "level": "ERROR", "logger": "server", "message": "Unhandled exception: ConnectionError: Database not connected. Call connect() first.", "module": "logging_config", "function": "log_with_context", "line": 119, "error_id": "4402254784", "error_type": "ConnectionError", "path": "/tasks/1", "method": "GET", "client": "testclient", "traceback": "Traceback (most recent call last):\n  File \"/Users/topiputih/Developments/company/sii/distributed-cracking/venv/lib/python3.11/site-packages/starlette/middleware/errors.py\", line 162, in __call__\n    await self.app(scope, receive, _send)\n  File \"/Users/topiputih/Developments/company/sii/distributed-cracking/venv/lib/python3.11/site-packages/starlette/middleware/cors.py\", line 83, in __call__\n    await self.app(scope, receive, send)\n  File \"/Users/topiputih/Developments/company/sii/distributed-cracking/venv/lib/python3.11/site-packages/starlette/middleware/exceptions.py\", line 79, in __call__\n    raise exc\n  File \"/Users/topiputih/Developments/company/sii/distributed-cracking/venv/lib/python3.11/site-packages/starlette/middleware/exceptions.py\", line 68, in __call__\n    await self.app(scope, receive, sender)\n  File \"/Users/topiputih/Developments/company/sii/distributed-cracking/venv/lib/python3.11/site-packages/fastapi/middleware/asyncexitstack.py\", line 20, in __call__\n    raise e\n  File \"/Users/topiputih/Developments/company/sii/distributed-cracking/venv/lib/python3.11/site-packages/fastapi/middleware/asyncexitstack.py\", line 17, in __call__\n    await self.app(scope, receive, send)\n  File \"/Users/topiputih/Developments/company/sii/distributed-cracking/venv/lib/python3.11/site-packages/starlette/routing.py\", line 718, in __call__\n    await route.handle(scope, receive, send)\n  File \"/Users/topiputih/Developments/company/sii/distributed-cracking/venv/lib/python3.11/site-packages/starlette/routing.py\", line 276, in handle\n    await self.app(scope, receive, send)\n  File \"/Users/topiputih/Developments/company/sii/distributed-cracking/venv/lib/python3.11/site-packages/starlette/routing.py\", line 66, in app\n    response = await func(request)\n               ^^^^^^^^^^^^^^^^^^^\n  File \"/Users/topiputih/Developments/company/sii/distributed-cracking/venv/lib/python3.11/site-packages/fastapi/routing.py\", line 264, in app\n    solved_result = await solve_dependencies(\n                    ^^^^^^^^^^^^^^^^^^^^^^^^^\n  File \"/Users/topiputih/Developments/company/sii/distributed-cracking/venv/lib/python3.11/site-packages/fastapi/dependencies/utils.py\", line 563, in solve_dependencies\n    solved_result = await solve_dependencies(\n                    ^^^^^^^^^^^^^^^^^^^^^^^^^\n  File \"/Users/topiputih/Developments/company/sii/distributed-cracking/venv/lib/python3.11/site-packages/fastapi/dependencies/utils.py\", line 563, in solve_dependencies\n    solved_result = await solve_dependencies(\n                    ^^^^^^^^^^^^^^^^^^^^^^^^^\n  File \"/Users/topiputih/Developments/company/sii/distributed-cracking/venv/lib/python3.11/site-packages/fastapi/dependencies/utils.py\", line 592, in solve_dependencies\n    solved = await call(**sub_values)\n             ^^^^^^^^^^^^^^^^^^^^^^^^\n  File \"/Users/topiputih/Developments/company/sii/distributed-cracking/cmd/server.py\", line 139, in get_db\n    db = Database.get_database()\n         ^^^^^^^^^^^^^^^^^^^^^^^\n  File \"/Users/topiputih/Developments/company/sii/distributed-cracking/config/database.py\", line 38, in get_database\n    raise ConnectionError(\"Database not connected. Call connect() first.\")\nConnectionError: Database not connected. Call connect() first.\n"}
{"timestamp": "2025-06-03T17:42:38.330700", "level": "ERROR", "logger": "server", "message": "Unhandled exception: ConnectionError: Database not connected. Call connect() first.", "module": "logging_config", "function": "log_with_context", "line": 119, "error_id": "4402256320", "error_type": "ConnectionError", "path": "/tasks", "method": "GET", "client": "testclient", "traceback": "Traceback (most recent call last):\n  File \"/Users/topiputih/Developments/company/sii/distributed-cracking/venv/lib/python3.11/site-packages/starlette/middleware/errors.py\", line 162, in __call__\n    await self.app(scope, receive, _send)\n  File \"/Users/topiputih/Developments/company/sii/distributed-cracking/venv/lib/python3.11/site-packages/starlette/middleware/cors.py\", line 83, in __call__\n    await self.app(scope, receive, send)\n  File \"/Users/topiputih/Developments/company/sii/distributed-cracking/venv/lib/python3.11/site-packages/starlette/middleware/exceptions.py\", line 79, in __call__\n    raise exc\n  File \"/Users/topiputih/Developments/company/sii/distributed-cracking/venv/lib/python3.11/site-packages/starlette/middleware/exceptions.py\", line 68, in __call__\n    await self.app(scope, receive, sender)\n  File \"/Users/topiputih/Developments/company/sii/distributed-cracking/venv/lib/python3.11/site-packages/fastapi/middleware/asyncexitstack.py\", line 20, in __call__\n    raise e\n  File \"/Users/topiputih/Developments/company/sii/distributed-cracking/venv/lib/python3.11/site-packages/fastapi/middleware/asyncexitstack.py\", line 17, in __call__\n    await self.app(scope, receive, send)\n  File \"/Users/topiputih/Developments/company/sii/distributed-cracking/venv/lib/python3.11/site-packages/starlette/routing.py\", line 718, in __call__\n    await route.handle(scope, receive, send)\n  File \"/Users/topiputih/Developments/company/sii/distributed-cracking/venv/lib/python3.11/site-packages/starlette/routing.py\", line 276, in handle\n    await self.app(scope, receive, send)\n  File \"/Users/topiputih/Developments/company/sii/distributed-cracking/venv/lib/python3.11/site-packages/starlette/routing.py\", line 66, in app\n    response = await func(request)\n               ^^^^^^^^^^^^^^^^^^^\n  File \"/Users/topiputih/Developments/company/sii/distributed-cracking/venv/lib/python3.11/site-packages/fastapi/routing.py\", line 264, in app\n    solved_result = await solve_dependencies(\n                    ^^^^^^^^^^^^^^^^^^^^^^^^^\n  File \"/Users/topiputih/Developments/company/sii/distributed-cracking/venv/lib/python3.11/site-packages/fastapi/dependencies/utils.py\", line 563, in solve_dependencies\n    solved_result = await solve_dependencies(\n                    ^^^^^^^^^^^^^^^^^^^^^^^^^\n  File \"/Users/topiputih/Developments/company/sii/distributed-cracking/venv/lib/python3.11/site-packages/fastapi/dependencies/utils.py\", line 563, in solve_dependencies\n    solved_result = await solve_dependencies(\n                    ^^^^^^^^^^^^^^^^^^^^^^^^^\n  File \"/Users/topiputih/Developments/company/sii/distributed-cracking/venv/lib/python3.11/site-packages/fastapi/dependencies/utils.py\", line 592, in solve_dependencies\n    solved = await call(**sub_values)\n             ^^^^^^^^^^^^^^^^^^^^^^^^\n  File \"/Users/topiputih/Developments/company/sii/distributed-cracking/cmd/server.py\", line 139, in get_db\n    db = Database.get_database()\n         ^^^^^^^^^^^^^^^^^^^^^^^\n  File \"/Users/topiputih/Developments/company/sii/distributed-cracking/config/database.py\", line 38, in get_database\n    raise ConnectionError(\"Database not connected. Call connect() first.\")\nConnectionError: Database not connected. Call connect() first.\n"}
{"timestamp": "2025-06-03T17:43:24.225381", "level": "ERROR", "logger": "server", "message": "Unhandled exception: ResourceNotFoundException: Task with id '1' not found", "module": "logging_config", "function": "log_with_context", "line": 119, "error_id": "4567208800", "error_type": "ResourceNotFoundException", "path": "/tasks/1", "method": "GET", "client": "testclient", "traceback": "Traceback (most recent call last):\n  File \"/Users/topiputih/Developments/company/sii/distributed-cracking/venv/lib/python3.11/site-packages/starlette/middleware/errors.py\", line 162, in __call__\n    await self.app(scope, receive, _send)\n  File \"/Users/topiputih/Developments/company/sii/distributed-cracking/venv/lib/python3.11/site-packages/starlette/middleware/cors.py\", line 83, in __call__\n    await self.app(scope, receive, send)\n  File \"/Users/topiputih/Developments/company/sii/distributed-cracking/venv/lib/python3.11/site-packages/starlette/middleware/exceptions.py\", line 79, in __call__\n    raise exc\n  File \"/Users/topiputih/Developments/company/sii/distributed-cracking/venv/lib/python3.11/site-packages/starlette/middleware/exceptions.py\", line 68, in __call__\n    await self.app(scope, receive, sender)\n  File \"/Users/topiputih/Developments/company/sii/distributed-cracking/venv/lib/python3.11/site-packages/fastapi/middleware/asyncexitstack.py\", line 20, in __call__\n    raise e\n  File \"/Users/topiputih/Developments/company/sii/distributed-cracking/venv/lib/python3.11/site-packages/fastapi/middleware/asyncexitstack.py\", line 17, in __call__\n    await self.app(scope, receive, send)\n  File \"/Users/topiputih/Developments/company/sii/distributed-cracking/venv/lib/python3.11/site-packages/starlette/routing.py\", line 718, in __call__\n    await route.handle(scope, receive, send)\n  File \"/Users/topiputih/Developments/company/sii/distributed-cracking/venv/lib/python3.11/site-packages/starlette/routing.py\", line 276, in handle\n    await self.app(scope, receive, send)\n  File \"/Users/topiputih/Developments/company/sii/distributed-cracking/venv/lib/python3.11/site-packages/starlette/routing.py\", line 66, in app\n    response = await func(request)\n               ^^^^^^^^^^^^^^^^^^^\n  File \"/Users/topiputih/Developments/company/sii/distributed-cracking/venv/lib/python3.11/site-packages/fastapi/routing.py\", line 274, in app\n    raw_response = await run_endpoint_function(\n                   ^^^^^^^^^^^^^^^^^^^^^^^^^^^^\n  File \"/Users/topiputih/Developments/company/sii/distributed-cracking/venv/lib/python3.11/site-packages/fastapi/routing.py\", line 191, in run_endpoint_function\n    return await dependant.call(**values)\n           ^^^^^^^^^^^^^^^^^^^^^^^^^^^^^^\n  File \"/Users/topiputih/Developments/company/sii/distributed-cracking/cmd/server.py\", line 370, in get_task\n    task = await task_usecase.get_task(task_id)\n           ^^^^^^^^^^^^^^^^^^^^^^^^^^^^^^^^^^^^\n  File \"/Users/topiputih/Developments/company/sii/distributed-cracking/usecase/task_usecase.py\", line 40, in get_task\n    raise ResourceNotFoundException(\nexception.usecase_exception.ResourceNotFoundException: Task with id '1' not found\n"}
{"timestamp": "2025-06-03T17:43:24.231806", "level": "ERROR", "logger": "server", "message": "Error retrieving tasks: object MagicMock can't be used in 'await' expression", "module": "logging_config", "function": "log_with_context", "line": 119, "error_type": "TypeError", "traceback": "Traceback (most recent call last):\n  File \"/Users/topiputih/Developments/company/sii/distributed-cracking/cmd/server.py\", line 336, in get_tasks\n    total = await task_usecase.count_all_tasks()\n            ^^^^^^^^^^^^^^^^^^^^^^^^^^^^^^^^^^^^\n  File \"/Users/topiputih/Developments/company/sii/distributed-cracking/usecase/task_usecase.py\", line 66, in count_all_tasks\n    return await self.task_repo.count_all()\n           ^^^^^^^^^^^^^^^^^^^^^^^^^^^^^^^^\n  File \"/Users/topiputih/Developments/company/sii/distributed-cracking/repository/task_repository.py\", line 88, in count_all\n    return await self.collection.count_documents({})\n           ^^^^^^^^^^^^^^^^^^^^^^^^^^^^^^^^^^^^^^^^^\nTypeError: object MagicMock can't be used in 'await' expression\n"}
{"timestamp": "2025-06-03T17:43:24.232256", "level": "ERROR", "logger": "server", "message": "Unhandled exception: TypeError: object MagicMock can't be used in 'await' expression", "module": "logging_config", "function": "log_with_context", "line": 119, "error_id": "4567214944", "error_type": "TypeError", "path": "/tasks", "method": "GET", "client": "testclient", "traceback": "Traceback (most recent call last):\n  File \"/Users/topiputih/Developments/company/sii/distributed-cracking/venv/lib/python3.11/site-packages/starlette/middleware/errors.py\", line 162, in __call__\n    await self.app(scope, receive, _send)\n  File \"/Users/topiputih/Developments/company/sii/distributed-cracking/venv/lib/python3.11/site-packages/starlette/middleware/cors.py\", line 83, in __call__\n    await self.app(scope, receive, send)\n  File \"/Users/topiputih/Developments/company/sii/distributed-cracking/venv/lib/python3.11/site-packages/starlette/middleware/exceptions.py\", line 79, in __call__\n    raise exc\n  File \"/Users/topiputih/Developments/company/sii/distributed-cracking/venv/lib/python3.11/site-packages/starlette/middleware/exceptions.py\", line 68, in __call__\n    await self.app(scope, receive, sender)\n  File \"/Users/topiputih/Developments/company/sii/distributed-cracking/venv/lib/python3.11/site-packages/fastapi/middleware/asyncexitstack.py\", line 20, in __call__\n    raise e\n  File \"/Users/topiputih/Developments/company/sii/distributed-cracking/venv/lib/python3.11/site-packages/fastapi/middleware/asyncexitstack.py\", line 17, in __call__\n    await self.app(scope, receive, send)\n  File \"/Users/topiputih/Developments/company/sii/distributed-cracking/venv/lib/python3.11/site-packages/starlette/routing.py\", line 718, in __call__\n    await route.handle(scope, receive, send)\n  File \"/Users/topiputih/Developments/company/sii/distributed-cracking/venv/lib/python3.11/site-packages/starlette/routing.py\", line 276, in handle\n    await self.app(scope, receive, send)\n  File \"/Users/topiputih/Developments/company/sii/distributed-cracking/venv/lib/python3.11/site-packages/starlette/routing.py\", line 66, in app\n    response = await func(request)\n               ^^^^^^^^^^^^^^^^^^^\n  File \"/Users/topiputih/Developments/company/sii/distributed-cracking/venv/lib/python3.11/site-packages/fastapi/routing.py\", line 274, in app\n    raw_response = await run_endpoint_function(\n                   ^^^^^^^^^^^^^^^^^^^^^^^^^^^^\n  File \"/Users/topiputih/Developments/company/sii/distributed-cracking/venv/lib/python3.11/site-packages/fastapi/routing.py\", line 191, in run_endpoint_function\n    return await dependant.call(**values)\n           ^^^^^^^^^^^^^^^^^^^^^^^^^^^^^^\n  File \"/Users/topiputih/Developments/company/sii/distributed-cracking/cmd/server.py\", line 336, in get_tasks\n    total = await task_usecase.count_all_tasks()\n            ^^^^^^^^^^^^^^^^^^^^^^^^^^^^^^^^^^^^\n  File \"/Users/topiputih/Developments/company/sii/distributed-cracking/usecase/task_usecase.py\", line 66, in count_all_tasks\n    return await self.task_repo.count_all()\n           ^^^^^^^^^^^^^^^^^^^^^^^^^^^^^^^^\n  File \"/Users/topiputih/Developments/company/sii/distributed-cracking/repository/task_repository.py\", line 88, in count_all\n    return await self.collection.count_documents({})\n           ^^^^^^^^^^^^^^^^^^^^^^^^^^^^^^^^^^^^^^^^^\nTypeError: object MagicMock can't be used in 'await' expression\n"}
{"timestamp": "2025-06-03T17:57:27.241200", "level": "ERROR", "logger": "server", "message": "Unhandled exception: ConnectionError: Database not connected. Call connect() first.", "module": "logging_config", "function": "log_with_context", "line": 119, "error_id": "4408424512", "error_type": "ConnectionError", "path": "/tasks", "method": "POST", "client": "testclient", "traceback": "Traceback (most recent call last):\n  File \"/Users/topiputih/Developments/company/sii/distributed-cracking/venv/lib/python3.11/site-packages/starlette/middleware/errors.py\", line 162, in __call__\n    await self.app(scope, receive, _send)\n  File \"/Users/topiputih/Developments/company/sii/distributed-cracking/venv/lib/python3.11/site-packages/starlette/middleware/cors.py\", line 83, in __call__\n    await self.app(scope, receive, send)\n  File \"/Users/topiputih/Developments/company/sii/distributed-cracking/venv/lib/python3.11/site-packages/starlette/middleware/exceptions.py\", line 79, in __call__\n    raise exc\n  File \"/Users/topiputih/Developments/company/sii/distributed-cracking/venv/lib/python3.11/site-packages/starlette/middleware/exceptions.py\", line 68, in __call__\n    await self.app(scope, receive, sender)\n  File \"/Users/topiputih/Developments/company/sii/distributed-cracking/venv/lib/python3.11/site-packages/fastapi/middleware/asyncexitstack.py\", line 20, in __call__\n    raise e\n  File \"/Users/topiputih/Developments/company/sii/distributed-cracking/venv/lib/python3.11/site-packages/fastapi/middleware/asyncexitstack.py\", line 17, in __call__\n    await self.app(scope, receive, send)\n  File \"/Users/topiputih/Developments/company/sii/distributed-cracking/venv/lib/python3.11/site-packages/starlette/routing.py\", line 718, in __call__\n    await route.handle(scope, receive, send)\n  File \"/Users/topiputih/Developments/company/sii/distributed-cracking/venv/lib/python3.11/site-packages/starlette/routing.py\", line 276, in handle\n    await self.app(scope, receive, send)\n  File \"/Users/topiputih/Developments/company/sii/distributed-cracking/venv/lib/python3.11/site-packages/starlette/routing.py\", line 66, in app\n    response = await func(request)\n               ^^^^^^^^^^^^^^^^^^^\n  File \"/Users/topiputih/Developments/company/sii/distributed-cracking/venv/lib/python3.11/site-packages/fastapi/routing.py\", line 264, in app\n    solved_result = await solve_dependencies(\n                    ^^^^^^^^^^^^^^^^^^^^^^^^^\n  File \"/Users/topiputih/Developments/company/sii/distributed-cracking/venv/lib/python3.11/site-packages/fastapi/dependencies/utils.py\", line 563, in solve_dependencies\n    solved_result = await solve_dependencies(\n                    ^^^^^^^^^^^^^^^^^^^^^^^^^\n  File \"/Users/topiputih/Developments/company/sii/distributed-cracking/venv/lib/python3.11/site-packages/fastapi/dependencies/utils.py\", line 563, in solve_dependencies\n    solved_result = await solve_dependencies(\n                    ^^^^^^^^^^^^^^^^^^^^^^^^^\n  File \"/Users/topiputih/Developments/company/sii/distributed-cracking/venv/lib/python3.11/site-packages/fastapi/dependencies/utils.py\", line 592, in solve_dependencies\n    solved = await call(**sub_values)\n             ^^^^^^^^^^^^^^^^^^^^^^^^\n  File \"/Users/topiputih/Developments/company/sii/distributed-cracking/_cmd_temp/server.py\", line 139, in get_db\n    db = Database.get_database()\n         ^^^^^^^^^^^^^^^^^^^^^^^\n  File \"/Users/topiputih/Developments/company/sii/distributed-cracking/config/database.py\", line 38, in get_database\n    raise ConnectionError(\"Database not connected. Call connect() first.\")\nConnectionError: Database not connected. Call connect() first.\n"}
{"timestamp": "2025-06-03T17:57:27.366545", "level": "ERROR", "logger": "server", "message": "Unhandled exception: ConnectionError: Database not connected. Call connect() first.", "module": "logging_config", "function": "log_with_context", "line": 119, "error_id": "4438844608", "error_type": "ConnectionError", "path": "/tasks", "method": "GET", "client": "testclient", "traceback": "Traceback (most recent call last):\n  File \"/Users/topiputih/Developments/company/sii/distributed-cracking/venv/lib/python3.11/site-packages/starlette/middleware/errors.py\", line 162, in __call__\n    await self.app(scope, receive, _send)\n  File \"/Users/topiputih/Developments/company/sii/distributed-cracking/venv/lib/python3.11/site-packages/starlette/middleware/cors.py\", line 83, in __call__\n    await self.app(scope, receive, send)\n  File \"/Users/topiputih/Developments/company/sii/distributed-cracking/venv/lib/python3.11/site-packages/starlette/middleware/exceptions.py\", line 79, in __call__\n    raise exc\n  File \"/Users/topiputih/Developments/company/sii/distributed-cracking/venv/lib/python3.11/site-packages/starlette/middleware/exceptions.py\", line 68, in __call__\n    await self.app(scope, receive, sender)\n  File \"/Users/topiputih/Developments/company/sii/distributed-cracking/venv/lib/python3.11/site-packages/fastapi/middleware/asyncexitstack.py\", line 20, in __call__\n    raise e\n  File \"/Users/topiputih/Developments/company/sii/distributed-cracking/venv/lib/python3.11/site-packages/fastapi/middleware/asyncexitstack.py\", line 17, in __call__\n    await self.app(scope, receive, send)\n  File \"/Users/topiputih/Developments/company/sii/distributed-cracking/venv/lib/python3.11/site-packages/starlette/routing.py\", line 718, in __call__\n    await route.handle(scope, receive, send)\n  File \"/Users/topiputih/Developments/company/sii/distributed-cracking/venv/lib/python3.11/site-packages/starlette/routing.py\", line 276, in handle\n    await self.app(scope, receive, send)\n  File \"/Users/topiputih/Developments/company/sii/distributed-cracking/venv/lib/python3.11/site-packages/starlette/routing.py\", line 66, in app\n    response = await func(request)\n               ^^^^^^^^^^^^^^^^^^^\n  File \"/Users/topiputih/Developments/company/sii/distributed-cracking/venv/lib/python3.11/site-packages/fastapi/routing.py\", line 264, in app\n    solved_result = await solve_dependencies(\n                    ^^^^^^^^^^^^^^^^^^^^^^^^^\n  File \"/Users/topiputih/Developments/company/sii/distributed-cracking/venv/lib/python3.11/site-packages/fastapi/dependencies/utils.py\", line 563, in solve_dependencies\n    solved_result = await solve_dependencies(\n                    ^^^^^^^^^^^^^^^^^^^^^^^^^\n  File \"/Users/topiputih/Developments/company/sii/distributed-cracking/venv/lib/python3.11/site-packages/fastapi/dependencies/utils.py\", line 563, in solve_dependencies\n    solved_result = await solve_dependencies(\n                    ^^^^^^^^^^^^^^^^^^^^^^^^^\n  File \"/Users/topiputih/Developments/company/sii/distributed-cracking/venv/lib/python3.11/site-packages/fastapi/dependencies/utils.py\", line 592, in solve_dependencies\n    solved = await call(**sub_values)\n             ^^^^^^^^^^^^^^^^^^^^^^^^\n  File \"/Users/topiputih/Developments/company/sii/distributed-cracking/_cmd_temp/server.py\", line 139, in get_db\n    db = Database.get_database()\n         ^^^^^^^^^^^^^^^^^^^^^^^\n  File \"/Users/topiputih/Developments/company/sii/distributed-cracking/config/database.py\", line 38, in get_database\n    raise ConnectionError(\"Database not connected. Call connect() first.\")\nConnectionError: Database not connected. Call connect() first.\n"}
{"timestamp": "2025-06-03T17:57:27.473769", "level": "ERROR", "logger": "server", "message": "Unhandled exception: ConnectionError: Database not connected. Call connect() first.", "module": "logging_config", "function": "log_with_context", "line": 119, "error_id": "4435108800", "error_type": "ConnectionError", "path": "/agents", "method": "POST", "client": "testclient", "traceback": "Traceback (most recent call last):\n  File \"/Users/topiputih/Developments/company/sii/distributed-cracking/venv/lib/python3.11/site-packages/starlette/middleware/errors.py\", line 162, in __call__\n    await self.app(scope, receive, _send)\n  File \"/Users/topiputih/Developments/company/sii/distributed-cracking/venv/lib/python3.11/site-packages/starlette/middleware/cors.py\", line 83, in __call__\n    await self.app(scope, receive, send)\n  File \"/Users/topiputih/Developments/company/sii/distributed-cracking/venv/lib/python3.11/site-packages/starlette/middleware/exceptions.py\", line 79, in __call__\n    raise exc\n  File \"/Users/topiputih/Developments/company/sii/distributed-cracking/venv/lib/python3.11/site-packages/starlette/middleware/exceptions.py\", line 68, in __call__\n    await self.app(scope, receive, sender)\n  File \"/Users/topiputih/Developments/company/sii/distributed-cracking/venv/lib/python3.11/site-packages/fastapi/middleware/asyncexitstack.py\", line 20, in __call__\n    raise e\n  File \"/Users/topiputih/Developments/company/sii/distributed-cracking/venv/lib/python3.11/site-packages/fastapi/middleware/asyncexitstack.py\", line 17, in __call__\n    await self.app(scope, receive, send)\n  File \"/Users/topiputih/Developments/company/sii/distributed-cracking/venv/lib/python3.11/site-packages/starlette/routing.py\", line 718, in __call__\n    await route.handle(scope, receive, send)\n  File \"/Users/topiputih/Developments/company/sii/distributed-cracking/venv/lib/python3.11/site-packages/starlette/routing.py\", line 276, in handle\n    await self.app(scope, receive, send)\n  File \"/Users/topiputih/Developments/company/sii/distributed-cracking/venv/lib/python3.11/site-packages/starlette/routing.py\", line 66, in app\n    response = await func(request)\n               ^^^^^^^^^^^^^^^^^^^\n  File \"/Users/topiputih/Developments/company/sii/distributed-cracking/venv/lib/python3.11/site-packages/fastapi/routing.py\", line 264, in app\n    solved_result = await solve_dependencies(\n                    ^^^^^^^^^^^^^^^^^^^^^^^^^\n  File \"/Users/topiputih/Developments/company/sii/distributed-cracking/venv/lib/python3.11/site-packages/fastapi/dependencies/utils.py\", line 563, in solve_dependencies\n    solved_result = await solve_dependencies(\n                    ^^^^^^^^^^^^^^^^^^^^^^^^^\n  File \"/Users/topiputih/Developments/company/sii/distributed-cracking/venv/lib/python3.11/site-packages/fastapi/dependencies/utils.py\", line 563, in solve_dependencies\n    solved_result = await solve_dependencies(\n                    ^^^^^^^^^^^^^^^^^^^^^^^^^\n  File \"/Users/topiputih/Developments/company/sii/distributed-cracking/venv/lib/python3.11/site-packages/fastapi/dependencies/utils.py\", line 592, in solve_dependencies\n    solved = await call(**sub_values)\n             ^^^^^^^^^^^^^^^^^^^^^^^^\n  File \"/Users/topiputih/Developments/company/sii/distributed-cracking/_cmd_temp/server.py\", line 139, in get_db\n    db = Database.get_database()\n         ^^^^^^^^^^^^^^^^^^^^^^^\n  File \"/Users/topiputih/Developments/company/sii/distributed-cracking/config/database.py\", line 38, in get_database\n    raise ConnectionError(\"Database not connected. Call connect() first.\")\nConnectionError: Database not connected. Call connect() first.\n"}
{"timestamp": "2025-06-03T17:59:25.806110", "level": "ERROR", "logger": "server", "message": "Error retrieving tasks: object MagicMock can't be used in 'await' expression", "module": "logging_config", "function": "log_with_context", "line": 119, "error_type": "TypeError", "traceback": "Traceback (most recent call last):\n  File \"/Users/topiputih/Developments/company/sii/distributed-cracking/_cmd_temp/server.py\", line 336, in get_tasks\n    total = await task_usecase.count_all_tasks()\n            ^^^^^^^^^^^^^^^^^^^^^^^^^^^^^^^^^^^^\n  File \"/Users/topiputih/Developments/company/sii/distributed-cracking/usecase/task_usecase.py\", line 66, in count_all_tasks\n    return await self.task_repo.count_all()\n           ^^^^^^^^^^^^^^^^^^^^^^^^^^^^^^^^\n  File \"/Users/topiputih/Developments/company/sii/distributed-cracking/repository/task_repository.py\", line 88, in count_all\n    return await self.collection.count_documents({})\n           ^^^^^^^^^^^^^^^^^^^^^^^^^^^^^^^^^^^^^^^^^\nTypeError: object MagicMock can't be used in 'await' expression\n"}
{"timestamp": "2025-06-03T17:59:25.809556", "level": "ERROR", "logger": "server", "message": "Unhandled exception: TypeError: object MagicMock can't be used in 'await' expression", "module": "logging_config", "function": "log_with_context", "line": 119, "error_id": "4431146208", "error_type": "TypeError", "path": "/tasks", "method": "GET", "client": "testclient", "traceback": "Traceback (most recent call last):\n  File \"/Users/topiputih/Developments/company/sii/distributed-cracking/venv/lib/python3.11/site-packages/starlette/middleware/errors.py\", line 162, in __call__\n    await self.app(scope, receive, _send)\n  File \"/Users/topiputih/Developments/company/sii/distributed-cracking/venv/lib/python3.11/site-packages/starlette/middleware/cors.py\", line 83, in __call__\n    await self.app(scope, receive, send)\n  File \"/Users/topiputih/Developments/company/sii/distributed-cracking/venv/lib/python3.11/site-packages/starlette/middleware/exceptions.py\", line 79, in __call__\n    raise exc\n  File \"/Users/topiputih/Developments/company/sii/distributed-cracking/venv/lib/python3.11/site-packages/starlette/middleware/exceptions.py\", line 68, in __call__\n    await self.app(scope, receive, sender)\n  File \"/Users/topiputih/Developments/company/sii/distributed-cracking/venv/lib/python3.11/site-packages/fastapi/middleware/asyncexitstack.py\", line 20, in __call__\n    raise e\n  File \"/Users/topiputih/Developments/company/sii/distributed-cracking/venv/lib/python3.11/site-packages/fastapi/middleware/asyncexitstack.py\", line 17, in __call__\n    await self.app(scope, receive, send)\n  File \"/Users/topiputih/Developments/company/sii/distributed-cracking/venv/lib/python3.11/site-packages/starlette/routing.py\", line 718, in __call__\n    await route.handle(scope, receive, send)\n  File \"/Users/topiputih/Developments/company/sii/distributed-cracking/venv/lib/python3.11/site-packages/starlette/routing.py\", line 276, in handle\n    await self.app(scope, receive, send)\n  File \"/Users/topiputih/Developments/company/sii/distributed-cracking/venv/lib/python3.11/site-packages/starlette/routing.py\", line 66, in app\n    response = await func(request)\n               ^^^^^^^^^^^^^^^^^^^\n  File \"/Users/topiputih/Developments/company/sii/distributed-cracking/venv/lib/python3.11/site-packages/fastapi/routing.py\", line 274, in app\n    raw_response = await run_endpoint_function(\n                   ^^^^^^^^^^^^^^^^^^^^^^^^^^^^\n  File \"/Users/topiputih/Developments/company/sii/distributed-cracking/venv/lib/python3.11/site-packages/fastapi/routing.py\", line 191, in run_endpoint_function\n    return await dependant.call(**values)\n           ^^^^^^^^^^^^^^^^^^^^^^^^^^^^^^\n  File \"/Users/topiputih/Developments/company/sii/distributed-cracking/_cmd_temp/server.py\", line 336, in get_tasks\n    total = await task_usecase.count_all_tasks()\n            ^^^^^^^^^^^^^^^^^^^^^^^^^^^^^^^^^^^^\n  File \"/Users/topiputih/Developments/company/sii/distributed-cracking/usecase/task_usecase.py\", line 66, in count_all_tasks\n    return await self.task_repo.count_all()\n           ^^^^^^^^^^^^^^^^^^^^^^^^^^^^^^^^\n  File \"/Users/topiputih/Developments/company/sii/distributed-cracking/repository/task_repository.py\", line 88, in count_all\n    return await self.collection.count_documents({})\n           ^^^^^^^^^^^^^^^^^^^^^^^^^^^^^^^^^^^^^^^^^\nTypeError: object MagicMock can't be used in 'await' expression\n"}
{"timestamp": "2025-06-03T18:00:32.158352", "level": "ERROR", "logger": "server", "message": "Error retrieving tasks: object MagicMock can't be used in 'await' expression", "module": "logging_config", "function": "log_with_context", "line": 119, "error_type": "TypeError", "traceback": "Traceback (most recent call last):\n  File \"/Users/topiputih/Developments/company/sii/distributed-cracking/_cmd_temp/server.py\", line 336, in get_tasks\n    total = await task_usecase.count_all_tasks()\n            ^^^^^^^^^^^^^^^^^^^^^^^^^^^^^^^^^^^^\n  File \"/Users/topiputih/Developments/company/sii/distributed-cracking/usecase/task_usecase.py\", line 66, in count_all_tasks\n    return await self.task_repo.count_all()\n           ^^^^^^^^^^^^^^^^^^^^^^^^^^^^^^^^\n  File \"/Users/topiputih/Developments/company/sii/distributed-cracking/repository/task_repository.py\", line 88, in count_all\n    return await self.collection.count_documents({})\n           ^^^^^^^^^^^^^^^^^^^^^^^^^^^^^^^^^^^^^^^^^\nTypeError: object MagicMock can't be used in 'await' expression\n"}
{"timestamp": "2025-06-03T18:00:32.161055", "level": "ERROR", "logger": "server", "message": "Unhandled exception: TypeError: object MagicMock can't be used in 'await' expression", "module": "logging_config", "function": "log_with_context", "line": 119, "error_id": "4607751744", "error_type": "TypeError", "path": "/tasks", "method": "GET", "client": "testclient", "traceback": "Traceback (most recent call last):\n  File \"/Users/topiputih/Developments/company/sii/distributed-cracking/venv/lib/python3.11/site-packages/starlette/middleware/errors.py\", line 162, in __call__\n    await self.app(scope, receive, _send)\n  File \"/Users/topiputih/Developments/company/sii/distributed-cracking/venv/lib/python3.11/site-packages/starlette/middleware/cors.py\", line 83, in __call__\n    await self.app(scope, receive, send)\n  File \"/Users/topiputih/Developments/company/sii/distributed-cracking/venv/lib/python3.11/site-packages/starlette/middleware/exceptions.py\", line 79, in __call__\n    raise exc\n  File \"/Users/topiputih/Developments/company/sii/distributed-cracking/venv/lib/python3.11/site-packages/starlette/middleware/exceptions.py\", line 68, in __call__\n    await self.app(scope, receive, sender)\n  File \"/Users/topiputih/Developments/company/sii/distributed-cracking/venv/lib/python3.11/site-packages/fastapi/middleware/asyncexitstack.py\", line 20, in __call__\n    raise e\n  File \"/Users/topiputih/Developments/company/sii/distributed-cracking/venv/lib/python3.11/site-packages/fastapi/middleware/asyncexitstack.py\", line 17, in __call__\n    await self.app(scope, receive, send)\n  File \"/Users/topiputih/Developments/company/sii/distributed-cracking/venv/lib/python3.11/site-packages/starlette/routing.py\", line 718, in __call__\n    await route.handle(scope, receive, send)\n  File \"/Users/topiputih/Developments/company/sii/distributed-cracking/venv/lib/python3.11/site-packages/starlette/routing.py\", line 276, in handle\n    await self.app(scope, receive, send)\n  File \"/Users/topiputih/Developments/company/sii/distributed-cracking/venv/lib/python3.11/site-packages/starlette/routing.py\", line 66, in app\n    response = await func(request)\n               ^^^^^^^^^^^^^^^^^^^\n  File \"/Users/topiputih/Developments/company/sii/distributed-cracking/venv/lib/python3.11/site-packages/fastapi/routing.py\", line 274, in app\n    raw_response = await run_endpoint_function(\n                   ^^^^^^^^^^^^^^^^^^^^^^^^^^^^\n  File \"/Users/topiputih/Developments/company/sii/distributed-cracking/venv/lib/python3.11/site-packages/fastapi/routing.py\", line 191, in run_endpoint_function\n    return await dependant.call(**values)\n           ^^^^^^^^^^^^^^^^^^^^^^^^^^^^^^\n  File \"/Users/topiputih/Developments/company/sii/distributed-cracking/_cmd_temp/server.py\", line 336, in get_tasks\n    total = await task_usecase.count_all_tasks()\n            ^^^^^^^^^^^^^^^^^^^^^^^^^^^^^^^^^^^^\n  File \"/Users/topiputih/Developments/company/sii/distributed-cracking/usecase/task_usecase.py\", line 66, in count_all_tasks\n    return await self.task_repo.count_all()\n           ^^^^^^^^^^^^^^^^^^^^^^^^^^^^^^^^\n  File \"/Users/topiputih/Developments/company/sii/distributed-cracking/repository/task_repository.py\", line 88, in count_all\n    return await self.collection.count_documents({})\n           ^^^^^^^^^^^^^^^^^^^^^^^^^^^^^^^^^^^^^^^^^\nTypeError: object MagicMock can't be used in 'await' expression\n"}
{"timestamp": "2025-06-03T18:05:57.789588", "level": "ERROR", "logger": "server", "message": "Error retrieving tasks: object MagicMock can't be used in 'await' expression", "module": "logging_config", "function": "log_with_context", "line": 119, "error_type": "TypeError", "traceback": "Traceback (most recent call last):\n  File \"/Users/topiputih/Developments/company/sii/distributed-cracking/_cmd_temp/server.py\", line 336, in get_tasks\n    total = await task_usecase.count_all_tasks()\n            ^^^^^^^^^^^^^^^^^^^^^^^^^^^^^^^^^^^^\n  File \"/Users/topiputih/Developments/company/sii/distributed-cracking/usecase/task_usecase.py\", line 66, in count_all_tasks\n    return await self.task_repo.count_all()\n           ^^^^^^^^^^^^^^^^^^^^^^^^^^^^^^^^\n  File \"/Users/topiputih/Developments/company/sii/distributed-cracking/repository/task_repository.py\", line 88, in count_all\n    return await self.collection.count_documents({})\n           ^^^^^^^^^^^^^^^^^^^^^^^^^^^^^^^^^^^^^^^^^\nTypeError: object MagicMock can't be used in 'await' expression\n"}
{"timestamp": "2025-06-03T18:05:57.792426", "level": "ERROR", "logger": "server", "message": "Unhandled exception: TypeError: object MagicMock can't be used in 'await' expression", "module": "logging_config", "function": "log_with_context", "line": 119, "error_id": "4403882752", "error_type": "TypeError", "path": "/tasks", "method": "GET", "client": "testclient", "traceback": "Traceback (most recent call last):\n  File \"/Users/topiputih/Developments/company/sii/distributed-cracking/venv/lib/python3.11/site-packages/starlette/middleware/errors.py\", line 162, in __call__\n    await self.app(scope, receive, _send)\n  File \"/Users/topiputih/Developments/company/sii/distributed-cracking/venv/lib/python3.11/site-packages/starlette/middleware/cors.py\", line 83, in __call__\n    await self.app(scope, receive, send)\n  File \"/Users/topiputih/Developments/company/sii/distributed-cracking/venv/lib/python3.11/site-packages/starlette/middleware/exceptions.py\", line 79, in __call__\n    raise exc\n  File \"/Users/topiputih/Developments/company/sii/distributed-cracking/venv/lib/python3.11/site-packages/starlette/middleware/exceptions.py\", line 68, in __call__\n    await self.app(scope, receive, sender)\n  File \"/Users/topiputih/Developments/company/sii/distributed-cracking/venv/lib/python3.11/site-packages/fastapi/middleware/asyncexitstack.py\", line 20, in __call__\n    raise e\n  File \"/Users/topiputih/Developments/company/sii/distributed-cracking/venv/lib/python3.11/site-packages/fastapi/middleware/asyncexitstack.py\", line 17, in __call__\n    await self.app(scope, receive, send)\n  File \"/Users/topiputih/Developments/company/sii/distributed-cracking/venv/lib/python3.11/site-packages/starlette/routing.py\", line 718, in __call__\n    await route.handle(scope, receive, send)\n  File \"/Users/topiputih/Developments/company/sii/distributed-cracking/venv/lib/python3.11/site-packages/starlette/routing.py\", line 276, in handle\n    await self.app(scope, receive, send)\n  File \"/Users/topiputih/Developments/company/sii/distributed-cracking/venv/lib/python3.11/site-packages/starlette/routing.py\", line 66, in app\n    response = await func(request)\n               ^^^^^^^^^^^^^^^^^^^\n  File \"/Users/topiputih/Developments/company/sii/distributed-cracking/venv/lib/python3.11/site-packages/fastapi/routing.py\", line 274, in app\n    raw_response = await run_endpoint_function(\n                   ^^^^^^^^^^^^^^^^^^^^^^^^^^^^\n  File \"/Users/topiputih/Developments/company/sii/distributed-cracking/venv/lib/python3.11/site-packages/fastapi/routing.py\", line 191, in run_endpoint_function\n    return await dependant.call(**values)\n           ^^^^^^^^^^^^^^^^^^^^^^^^^^^^^^\n  File \"/Users/topiputih/Developments/company/sii/distributed-cracking/_cmd_temp/server.py\", line 336, in get_tasks\n    total = await task_usecase.count_all_tasks()\n            ^^^^^^^^^^^^^^^^^^^^^^^^^^^^^^^^^^^^\n  File \"/Users/topiputih/Developments/company/sii/distributed-cracking/usecase/task_usecase.py\", line 66, in count_all_tasks\n    return await self.task_repo.count_all()\n           ^^^^^^^^^^^^^^^^^^^^^^^^^^^^^^^^\n  File \"/Users/topiputih/Developments/company/sii/distributed-cracking/repository/task_repository.py\", line 88, in count_all\n    return await self.collection.count_documents({})\n           ^^^^^^^^^^^^^^^^^^^^^^^^^^^^^^^^^^^^^^^^^\nTypeError: object MagicMock can't be used in 'await' expression\n"}
{"timestamp": "2025-06-03T18:08:31.931715", "level": "ERROR", "logger": "server", "message": "Error retrieving tasks: object MagicMock can't be used in 'await' expression", "module": "logging_config", "function": "log_with_context", "line": 119, "error_type": "TypeError", "traceback": "Traceback (most recent call last):\n  File \"/Users/topiputih/Developments/company/sii/distributed-cracking/_cmd_temp/server.py\", line 336, in get_tasks\n    total = await task_usecase.count_all_tasks()\n            ^^^^^^^^^^^^^^^^^^^^^^^^^^^^^^^^^^^^\n  File \"/Users/topiputih/Developments/company/sii/distributed-cracking/usecase/task_usecase.py\", line 66, in count_all_tasks\n    return await self.task_repo.count_all()\n           ^^^^^^^^^^^^^^^^^^^^^^^^^^^^^^^^\n  File \"/Users/topiputih/Developments/company/sii/distributed-cracking/repository/task_repository.py\", line 88, in count_all\n    return await self.collection.count_documents({})\n           ^^^^^^^^^^^^^^^^^^^^^^^^^^^^^^^^^^^^^^^^^\nTypeError: object MagicMock can't be used in 'await' expression\n"}
{"timestamp": "2025-06-03T18:08:31.934730", "level": "ERROR", "logger": "server", "message": "Unhandled exception: TypeError: object MagicMock can't be used in 'await' expression", "module": "logging_config", "function": "log_with_context", "line": 119, "error_id": "4398955296", "error_type": "TypeError", "path": "/tasks", "method": "GET", "client": "testclient", "traceback": "Traceback (most recent call last):\n  File \"/Users/topiputih/Developments/company/sii/distributed-cracking/venv/lib/python3.11/site-packages/starlette/middleware/errors.py\", line 162, in __call__\n    await self.app(scope, receive, _send)\n  File \"/Users/topiputih/Developments/company/sii/distributed-cracking/venv/lib/python3.11/site-packages/starlette/middleware/cors.py\", line 83, in __call__\n    await self.app(scope, receive, send)\n  File \"/Users/topiputih/Developments/company/sii/distributed-cracking/venv/lib/python3.11/site-packages/starlette/middleware/exceptions.py\", line 79, in __call__\n    raise exc\n  File \"/Users/topiputih/Developments/company/sii/distributed-cracking/venv/lib/python3.11/site-packages/starlette/middleware/exceptions.py\", line 68, in __call__\n    await self.app(scope, receive, sender)\n  File \"/Users/topiputih/Developments/company/sii/distributed-cracking/venv/lib/python3.11/site-packages/fastapi/middleware/asyncexitstack.py\", line 20, in __call__\n    raise e\n  File \"/Users/topiputih/Developments/company/sii/distributed-cracking/venv/lib/python3.11/site-packages/fastapi/middleware/asyncexitstack.py\", line 17, in __call__\n    await self.app(scope, receive, send)\n  File \"/Users/topiputih/Developments/company/sii/distributed-cracking/venv/lib/python3.11/site-packages/starlette/routing.py\", line 718, in __call__\n    await route.handle(scope, receive, send)\n  File \"/Users/topiputih/Developments/company/sii/distributed-cracking/venv/lib/python3.11/site-packages/starlette/routing.py\", line 276, in handle\n    await self.app(scope, receive, send)\n  File \"/Users/topiputih/Developments/company/sii/distributed-cracking/venv/lib/python3.11/site-packages/starlette/routing.py\", line 66, in app\n    response = await func(request)\n               ^^^^^^^^^^^^^^^^^^^\n  File \"/Users/topiputih/Developments/company/sii/distributed-cracking/venv/lib/python3.11/site-packages/fastapi/routing.py\", line 274, in app\n    raw_response = await run_endpoint_function(\n                   ^^^^^^^^^^^^^^^^^^^^^^^^^^^^\n  File \"/Users/topiputih/Developments/company/sii/distributed-cracking/venv/lib/python3.11/site-packages/fastapi/routing.py\", line 191, in run_endpoint_function\n    return await dependant.call(**values)\n           ^^^^^^^^^^^^^^^^^^^^^^^^^^^^^^\n  File \"/Users/topiputih/Developments/company/sii/distributed-cracking/_cmd_temp/server.py\", line 336, in get_tasks\n    total = await task_usecase.count_all_tasks()\n            ^^^^^^^^^^^^^^^^^^^^^^^^^^^^^^^^^^^^\n  File \"/Users/topiputih/Developments/company/sii/distributed-cracking/usecase/task_usecase.py\", line 66, in count_all_tasks\n    return await self.task_repo.count_all()\n           ^^^^^^^^^^^^^^^^^^^^^^^^^^^^^^^^\n  File \"/Users/topiputih/Developments/company/sii/distributed-cracking/repository/task_repository.py\", line 88, in count_all\n    return await self.collection.count_documents({})\n           ^^^^^^^^^^^^^^^^^^^^^^^^^^^^^^^^^^^^^^^^^\nTypeError: object MagicMock can't be used in 'await' expression\n"}
{"timestamp": "2025-06-03T18:09:45.321581", "level": "ERROR", "logger": "server", "message": "Error retrieving tasks: object MagicMock can't be used in 'await' expression", "module": "logging_config", "function": "log_with_context", "line": 119, "error_type": "TypeError", "traceback": "Traceback (most recent call last):\n  File \"/Users/topiputih/Developments/company/sii/distributed-cracking/_cmd_temp/server.py\", line 336, in get_tasks\n    total = await task_usecase.count_all_tasks()\n            ^^^^^^^^^^^^^^^^^^^^^^^^^^^^^^^^^^^^\n  File \"/Users/topiputih/Developments/company/sii/distributed-cracking/usecase/task_usecase.py\", line 66, in count_all_tasks\n    return await self.task_repo.count_all()\n           ^^^^^^^^^^^^^^^^^^^^^^^^^^^^^^^^\n  File \"/Users/topiputih/Developments/company/sii/distributed-cracking/repository/task_repository.py\", line 88, in count_all\n    return await self.collection.count_documents({})\n           ^^^^^^^^^^^^^^^^^^^^^^^^^^^^^^^^^^^^^^^^^\nTypeError: object MagicMock can't be used in 'await' expression\n"}
{"timestamp": "2025-06-03T18:09:45.324708", "level": "ERROR", "logger": "server", "message": "Unhandled exception: TypeError: object MagicMock can't be used in 'await' expression", "module": "logging_config", "function": "log_with_context", "line": 119, "error_id": "4617561344", "error_type": "TypeError", "path": "/tasks", "method": "GET", "client": "testclient", "traceback": "Traceback (most recent call last):\n  File \"/Users/topiputih/Developments/company/sii/distributed-cracking/venv/lib/python3.11/site-packages/starlette/middleware/errors.py\", line 162, in __call__\n    await self.app(scope, receive, _send)\n  File \"/Users/topiputih/Developments/company/sii/distributed-cracking/venv/lib/python3.11/site-packages/starlette/middleware/cors.py\", line 83, in __call__\n    await self.app(scope, receive, send)\n  File \"/Users/topiputih/Developments/company/sii/distributed-cracking/venv/lib/python3.11/site-packages/starlette/middleware/exceptions.py\", line 79, in __call__\n    raise exc\n  File \"/Users/topiputih/Developments/company/sii/distributed-cracking/venv/lib/python3.11/site-packages/starlette/middleware/exceptions.py\", line 68, in __call__\n    await self.app(scope, receive, sender)\n  File \"/Users/topiputih/Developments/company/sii/distributed-cracking/venv/lib/python3.11/site-packages/fastapi/middleware/asyncexitstack.py\", line 20, in __call__\n    raise e\n  File \"/Users/topiputih/Developments/company/sii/distributed-cracking/venv/lib/python3.11/site-packages/fastapi/middleware/asyncexitstack.py\", line 17, in __call__\n    await self.app(scope, receive, send)\n  File \"/Users/topiputih/Developments/company/sii/distributed-cracking/venv/lib/python3.11/site-packages/starlette/routing.py\", line 718, in __call__\n    await route.handle(scope, receive, send)\n  File \"/Users/topiputih/Developments/company/sii/distributed-cracking/venv/lib/python3.11/site-packages/starlette/routing.py\", line 276, in handle\n    await self.app(scope, receive, send)\n  File \"/Users/topiputih/Developments/company/sii/distributed-cracking/venv/lib/python3.11/site-packages/starlette/routing.py\", line 66, in app\n    response = await func(request)\n               ^^^^^^^^^^^^^^^^^^^\n  File \"/Users/topiputih/Developments/company/sii/distributed-cracking/venv/lib/python3.11/site-packages/fastapi/routing.py\", line 274, in app\n    raw_response = await run_endpoint_function(\n                   ^^^^^^^^^^^^^^^^^^^^^^^^^^^^\n  File \"/Users/topiputih/Developments/company/sii/distributed-cracking/venv/lib/python3.11/site-packages/fastapi/routing.py\", line 191, in run_endpoint_function\n    return await dependant.call(**values)\n           ^^^^^^^^^^^^^^^^^^^^^^^^^^^^^^\n  File \"/Users/topiputih/Developments/company/sii/distributed-cracking/_cmd_temp/server.py\", line 336, in get_tasks\n    total = await task_usecase.count_all_tasks()\n            ^^^^^^^^^^^^^^^^^^^^^^^^^^^^^^^^^^^^\n  File \"/Users/topiputih/Developments/company/sii/distributed-cracking/usecase/task_usecase.py\", line 66, in count_all_tasks\n    return await self.task_repo.count_all()\n           ^^^^^^^^^^^^^^^^^^^^^^^^^^^^^^^^\n  File \"/Users/topiputih/Developments/company/sii/distributed-cracking/repository/task_repository.py\", line 88, in count_all\n    return await self.collection.count_documents({})\n           ^^^^^^^^^^^^^^^^^^^^^^^^^^^^^^^^^^^^^^^^^\nTypeError: object MagicMock can't be used in 'await' expression\n"}
{"timestamp": "2025-06-03T18:09:45.428702", "level": "ERROR", "logger": "server", "message": "Unhandled exception: TypeError: object MagicMock can't be used in 'await' expression", "module": "logging_config", "function": "log_with_context", "line": 119, "error_id": "4620082080", "error_type": "TypeError", "path": "/agents", "method": "POST", "client": "testclient", "traceback": "Traceback (most recent call last):\n  File \"/Users/topiputih/Developments/company/sii/distributed-cracking/venv/lib/python3.11/site-packages/starlette/middleware/errors.py\", line 162, in __call__\n    await self.app(scope, receive, _send)\n  File \"/Users/topiputih/Developments/company/sii/distributed-cracking/venv/lib/python3.11/site-packages/starlette/middleware/cors.py\", line 83, in __call__\n    await self.app(scope, receive, send)\n  File \"/Users/topiputih/Developments/company/sii/distributed-cracking/venv/lib/python3.11/site-packages/starlette/middleware/exceptions.py\", line 79, in __call__\n    raise exc\n  File \"/Users/topiputih/Developments/company/sii/distributed-cracking/venv/lib/python3.11/site-packages/starlette/middleware/exceptions.py\", line 68, in __call__\n    await self.app(scope, receive, sender)\n  File \"/Users/topiputih/Developments/company/sii/distributed-cracking/venv/lib/python3.11/site-packages/fastapi/middleware/asyncexitstack.py\", line 20, in __call__\n    raise e\n  File \"/Users/topiputih/Developments/company/sii/distributed-cracking/venv/lib/python3.11/site-packages/fastapi/middleware/asyncexitstack.py\", line 17, in __call__\n    await self.app(scope, receive, send)\n  File \"/Users/topiputih/Developments/company/sii/distributed-cracking/venv/lib/python3.11/site-packages/starlette/routing.py\", line 718, in __call__\n    await route.handle(scope, receive, send)\n  File \"/Users/topiputih/Developments/company/sii/distributed-cracking/venv/lib/python3.11/site-packages/starlette/routing.py\", line 276, in handle\n    await self.app(scope, receive, send)\n  File \"/Users/topiputih/Developments/company/sii/distributed-cracking/venv/lib/python3.11/site-packages/starlette/routing.py\", line 66, in app\n    response = await func(request)\n               ^^^^^^^^^^^^^^^^^^^\n  File \"/Users/topiputih/Developments/company/sii/distributed-cracking/venv/lib/python3.11/site-packages/fastapi/routing.py\", line 274, in app\n    raw_response = await run_endpoint_function(\n                   ^^^^^^^^^^^^^^^^^^^^^^^^^^^^\n  File \"/Users/topiputih/Developments/company/sii/distributed-cracking/venv/lib/python3.11/site-packages/fastapi/routing.py\", line 191, in run_endpoint_function\n    return await dependant.call(**values)\n           ^^^^^^^^^^^^^^^^^^^^^^^^^^^^^^\n  File \"/Users/topiputih/Developments/company/sii/distributed-cracking/_cmd_temp/server.py\", line 562, in register_agent\n    registered_agent = await agent_usecase.register_agent(agent)\n                       ^^^^^^^^^^^^^^^^^^^^^^^^^^^^^^^^^^^^^^^^^\n  File \"/Users/topiputih/Developments/company/sii/distributed-cracking/usecase/agent_usecase.py\", line 29, in register_agent\n    return await self.agent_repo.create(agent)\n           ^^^^^^^^^^^^^^^^^^^^^^^^^^^^^^^^^^^\n  File \"/Users/topiputih/Developments/company/sii/distributed-cracking/repository/agent_repository.py\", line 22, in create\n    result = await self.collection.insert_one(agent_dict)\n             ^^^^^^^^^^^^^^^^^^^^^^^^^^^^^^^^^^^^^^^^^^^^\nTypeError: object MagicMock can't be used in 'await' expression\n"}
{"timestamp": "2025-06-03T18:17:03.224449", "level": "ERROR", "logger": "server", "message": "Unhandled exception: AttributeError: 'MockDatabase' object has no attribute 'results'", "module": "logging_config", "function": "log_with_context", "line": 119, "error_id": "4409786768", "error_type": "AttributeError", "path": "/tasks", "method": "POST", "client": "testclient", "traceback": "Traceback (most recent call last):\n  File \"/Users/topiputih/Developments/company/sii/distributed-cracking/venv/lib/python3.11/site-packages/starlette/middleware/errors.py\", line 162, in __call__\n    await self.app(scope, receive, _send)\n  File \"/Users/topiputih/Developments/company/sii/distributed-cracking/venv/lib/python3.11/site-packages/starlette/middleware/cors.py\", line 83, in __call__\n    await self.app(scope, receive, send)\n  File \"/Users/topiputih/Developments/company/sii/distributed-cracking/venv/lib/python3.11/site-packages/starlette/middleware/exceptions.py\", line 79, in __call__\n    raise exc\n  File \"/Users/topiputih/Developments/company/sii/distributed-cracking/venv/lib/python3.11/site-packages/starlette/middleware/exceptions.py\", line 68, in __call__\n    await self.app(scope, receive, sender)\n  File \"/Users/topiputih/Developments/company/sii/distributed-cracking/venv/lib/python3.11/site-packages/fastapi/middleware/asyncexitstack.py\", line 20, in __call__\n    raise e\n  File \"/Users/topiputih/Developments/company/sii/distributed-cracking/venv/lib/python3.11/site-packages/fastapi/middleware/asyncexitstack.py\", line 17, in __call__\n    await self.app(scope, receive, send)\n  File \"/Users/topiputih/Developments/company/sii/distributed-cracking/venv/lib/python3.11/site-packages/starlette/routing.py\", line 718, in __call__\n    await route.handle(scope, receive, send)\n  File \"/Users/topiputih/Developments/company/sii/distributed-cracking/venv/lib/python3.11/site-packages/starlette/routing.py\", line 276, in handle\n    await self.app(scope, receive, send)\n  File \"/Users/topiputih/Developments/company/sii/distributed-cracking/venv/lib/python3.11/site-packages/starlette/routing.py\", line 66, in app\n    response = await func(request)\n               ^^^^^^^^^^^^^^^^^^^\n  File \"/Users/topiputih/Developments/company/sii/distributed-cracking/venv/lib/python3.11/site-packages/fastapi/routing.py\", line 264, in app\n    solved_result = await solve_dependencies(\n                    ^^^^^^^^^^^^^^^^^^^^^^^^^\n  File \"/Users/topiputih/Developments/company/sii/distributed-cracking/venv/lib/python3.11/site-packages/fastapi/dependencies/utils.py\", line 563, in solve_dependencies\n    solved_result = await solve_dependencies(\n                    ^^^^^^^^^^^^^^^^^^^^^^^^^\n  File \"/Users/topiputih/Developments/company/sii/distributed-cracking/venv/lib/python3.11/site-packages/fastapi/dependencies/utils.py\", line 592, in solve_dependencies\n    solved = await call(**sub_values)\n             ^^^^^^^^^^^^^^^^^^^^^^^^\n  File \"/Users/topiputih/Developments/company/sii/distributed-cracking/_cmd_temp/server.py\", line 150, in get_result_repo\n    return ResultRepository(db)\n           ^^^^^^^^^^^^^^^^^^^^\n  File \"/Users/topiputih/Developments/company/sii/distributed-cracking/repository/result_repository.py\", line 13, in __init__\n    self.collection = database.results\n                      ^^^^^^^^^^^^^^^^\nAttributeError: 'MockDatabase' object has no attribute 'results'\n"}
{"timestamp": "2025-06-03T18:17:03.359075", "level": "ERROR", "logger": "server", "message": "Unhandled exception: AttributeError: 'MockDatabase' object has no attribute 'results'", "module": "logging_config", "function": "log_with_context", "line": 119, "error_id": "4412911488", "error_type": "AttributeError", "path": "/tasks", "method": "GET", "client": "testclient", "traceback": "Traceback (most recent call last):\n  File \"/Users/topiputih/Developments/company/sii/distributed-cracking/venv/lib/python3.11/site-packages/starlette/middleware/errors.py\", line 162, in __call__\n    await self.app(scope, receive, _send)\n  File \"/Users/topiputih/Developments/company/sii/distributed-cracking/venv/lib/python3.11/site-packages/starlette/middleware/cors.py\", line 83, in __call__\n    await self.app(scope, receive, send)\n  File \"/Users/topiputih/Developments/company/sii/distributed-cracking/venv/lib/python3.11/site-packages/starlette/middleware/exceptions.py\", line 79, in __call__\n    raise exc\n  File \"/Users/topiputih/Developments/company/sii/distributed-cracking/venv/lib/python3.11/site-packages/starlette/middleware/exceptions.py\", line 68, in __call__\n    await self.app(scope, receive, sender)\n  File \"/Users/topiputih/Developments/company/sii/distributed-cracking/venv/lib/python3.11/site-packages/fastapi/middleware/asyncexitstack.py\", line 20, in __call__\n    raise e\n  File \"/Users/topiputih/Developments/company/sii/distributed-cracking/venv/lib/python3.11/site-packages/fastapi/middleware/asyncexitstack.py\", line 17, in __call__\n    await self.app(scope, receive, send)\n  File \"/Users/topiputih/Developments/company/sii/distributed-cracking/venv/lib/python3.11/site-packages/starlette/routing.py\", line 718, in __call__\n    await route.handle(scope, receive, send)\n  File \"/Users/topiputih/Developments/company/sii/distributed-cracking/venv/lib/python3.11/site-packages/starlette/routing.py\", line 276, in handle\n    await self.app(scope, receive, send)\n  File \"/Users/topiputih/Developments/company/sii/distributed-cracking/venv/lib/python3.11/site-packages/starlette/routing.py\", line 66, in app\n    response = await func(request)\n               ^^^^^^^^^^^^^^^^^^^\n  File \"/Users/topiputih/Developments/company/sii/distributed-cracking/venv/lib/python3.11/site-packages/fastapi/routing.py\", line 264, in app\n    solved_result = await solve_dependencies(\n                    ^^^^^^^^^^^^^^^^^^^^^^^^^\n  File \"/Users/topiputih/Developments/company/sii/distributed-cracking/venv/lib/python3.11/site-packages/fastapi/dependencies/utils.py\", line 563, in solve_dependencies\n    solved_result = await solve_dependencies(\n                    ^^^^^^^^^^^^^^^^^^^^^^^^^\n  File \"/Users/topiputih/Developments/company/sii/distributed-cracking/venv/lib/python3.11/site-packages/fastapi/dependencies/utils.py\", line 592, in solve_dependencies\n    solved = await call(**sub_values)\n             ^^^^^^^^^^^^^^^^^^^^^^^^\n  File \"/Users/topiputih/Developments/company/sii/distributed-cracking/_cmd_temp/server.py\", line 150, in get_result_repo\n    return ResultRepository(db)\n           ^^^^^^^^^^^^^^^^^^^^\n  File \"/Users/topiputih/Developments/company/sii/distributed-cracking/repository/result_repository.py\", line 13, in __init__\n    self.collection = database.results\n                      ^^^^^^^^^^^^^^^^\nAttributeError: 'MockDatabase' object has no attribute 'results'\n"}
{"timestamp": "2025-06-03T18:18:06.432013", "level": "ERROR", "logger": "server", "message": "Error retrieving tasks: 'coroutine' object has no attribute 'skip'", "module": "logging_config", "function": "log_with_context", "line": 119, "error_type": "AttributeError", "traceback": "Traceback (most recent call last):\n  File \"/Users/topiputih/Developments/company/sii/distributed-cracking/_cmd_temp/server.py\", line 337, in get_tasks\n    tasks = await task_usecase.get_all_tasks(pagination.skip, pagination.limit)\n            ^^^^^^^^^^^^^^^^^^^^^^^^^^^^^^^^^^^^^^^^^^^^^^^^^^^^^^^^^^^^^^^^^^^\n  File \"/Users/topiputih/Developments/company/sii/distributed-cracking/usecase/task_usecase.py\", line 58, in get_all_tasks\n    return await self.task_repo.find_all(skip, limit)\n           ^^^^^^^^^^^^^^^^^^^^^^^^^^^^^^^^^^^^^^^^^^\n  File \"/Users/topiputih/Developments/company/sii/distributed-cracking/repository/task_repository.py\", line 72, in find_all\n    cursor = self.collection.find().skip(skip).limit(limit)\n             ^^^^^^^^^^^^^^^^^^^^^^^^^^^\nAttributeError: 'coroutine' object has no attribute 'skip'\n"}
{"timestamp": "2025-06-03T18:18:06.434662", "level": "ERROR", "logger": "server", "message": "Unhandled exception: AttributeError: 'coroutine' object has no attribute 'skip'", "module": "logging_config", "function": "log_with_context", "line": 119, "error_id": "4848935408", "error_type": "AttributeError", "path": "/tasks", "method": "GET", "client": "testclient", "traceback": "Traceback (most recent call last):\n  File \"/Users/topiputih/Developments/company/sii/distributed-cracking/venv/lib/python3.11/site-packages/starlette/middleware/errors.py\", line 162, in __call__\n    await self.app(scope, receive, _send)\n  File \"/Users/topiputih/Developments/company/sii/distributed-cracking/venv/lib/python3.11/site-packages/starlette/middleware/cors.py\", line 83, in __call__\n    await self.app(scope, receive, send)\n  File \"/Users/topiputih/Developments/company/sii/distributed-cracking/venv/lib/python3.11/site-packages/starlette/middleware/exceptions.py\", line 79, in __call__\n    raise exc\n  File \"/Users/topiputih/Developments/company/sii/distributed-cracking/venv/lib/python3.11/site-packages/starlette/middleware/exceptions.py\", line 68, in __call__\n    await self.app(scope, receive, sender)\n  File \"/Users/topiputih/Developments/company/sii/distributed-cracking/venv/lib/python3.11/site-packages/fastapi/middleware/asyncexitstack.py\", line 20, in __call__\n    raise e\n  File \"/Users/topiputih/Developments/company/sii/distributed-cracking/venv/lib/python3.11/site-packages/fastapi/middleware/asyncexitstack.py\", line 17, in __call__\n    await self.app(scope, receive, send)\n  File \"/Users/topiputih/Developments/company/sii/distributed-cracking/venv/lib/python3.11/site-packages/starlette/routing.py\", line 718, in __call__\n    await route.handle(scope, receive, send)\n  File \"/Users/topiputih/Developments/company/sii/distributed-cracking/venv/lib/python3.11/site-packages/starlette/routing.py\", line 276, in handle\n    await self.app(scope, receive, send)\n  File \"/Users/topiputih/Developments/company/sii/distributed-cracking/venv/lib/python3.11/site-packages/starlette/routing.py\", line 66, in app\n    response = await func(request)\n               ^^^^^^^^^^^^^^^^^^^\n  File \"/Users/topiputih/Developments/company/sii/distributed-cracking/venv/lib/python3.11/site-packages/fastapi/routing.py\", line 274, in app\n    raw_response = await run_endpoint_function(\n                   ^^^^^^^^^^^^^^^^^^^^^^^^^^^^\n  File \"/Users/topiputih/Developments/company/sii/distributed-cracking/venv/lib/python3.11/site-packages/fastapi/routing.py\", line 191, in run_endpoint_function\n    return await dependant.call(**values)\n           ^^^^^^^^^^^^^^^^^^^^^^^^^^^^^^\n  File \"/Users/topiputih/Developments/company/sii/distributed-cracking/_cmd_temp/server.py\", line 337, in get_tasks\n    tasks = await task_usecase.get_all_tasks(pagination.skip, pagination.limit)\n            ^^^^^^^^^^^^^^^^^^^^^^^^^^^^^^^^^^^^^^^^^^^^^^^^^^^^^^^^^^^^^^^^^^^\n  File \"/Users/topiputih/Developments/company/sii/distributed-cracking/usecase/task_usecase.py\", line 58, in get_all_tasks\n    return await self.task_repo.find_all(skip, limit)\n           ^^^^^^^^^^^^^^^^^^^^^^^^^^^^^^^^^^^^^^^^^^\n  File \"/Users/topiputih/Developments/company/sii/distributed-cracking/repository/task_repository.py\", line 72, in find_all\n    cursor = self.collection.find().skip(skip).limit(limit)\n             ^^^^^^^^^^^^^^^^^^^^^^^^^^^\nAttributeError: 'coroutine' object has no attribute 'skip'\n"}
{"timestamp": "2025-06-03T18:20:35.306277", "level": "ERROR", "logger": "server", "message": "Error retrieving tasks: 'coroutine' object has no attribute 'skip'", "module": "logging_config", "function": "log_with_context", "line": 119, "error_type": "AttributeError", "traceback": "Traceback (most recent call last):\n  File \"/Users/topiputih/Developments/company/sii/distributed-cracking/_cmd_temp/server.py\", line 337, in get_tasks\n    tasks = await task_usecase.get_all_tasks(pagination.skip, pagination.limit)\n            ^^^^^^^^^^^^^^^^^^^^^^^^^^^^^^^^^^^^^^^^^^^^^^^^^^^^^^^^^^^^^^^^^^^\n  File \"/Users/topiputih/Developments/company/sii/distributed-cracking/usecase/task_usecase.py\", line 58, in get_all_tasks\n    return await self.task_repo.find_all(skip, limit)\n           ^^^^^^^^^^^^^^^^^^^^^^^^^^^^^^^^^^^^^^^^^^\n  File \"/Users/topiputih/Developments/company/sii/distributed-cracking/repository/task_repository.py\", line 72, in find_all\n    cursor = self.collection.find().skip(skip).limit(limit)\n             ^^^^^^^^^^^^^^^^^^^^^^^^^^^\nAttributeError: 'coroutine' object has no attribute 'skip'\n"}
{"timestamp": "2025-06-03T18:20:35.310009", "level": "ERROR", "logger": "server", "message": "Unhandled exception: AttributeError: 'coroutine' object has no attribute 'skip'", "module": "logging_config", "function": "log_with_context", "line": 119, "error_id": "4587858272", "error_type": "AttributeError", "path": "/tasks", "method": "GET", "client": "testclient", "traceback": "Traceback (most recent call last):\n  File \"/Users/topiputih/Developments/company/sii/distributed-cracking/venv/lib/python3.11/site-packages/starlette/middleware/errors.py\", line 162, in __call__\n    await self.app(scope, receive, _send)\n  File \"/Users/topiputih/Developments/company/sii/distributed-cracking/venv/lib/python3.11/site-packages/starlette/middleware/cors.py\", line 83, in __call__\n    await self.app(scope, receive, send)\n  File \"/Users/topiputih/Developments/company/sii/distributed-cracking/venv/lib/python3.11/site-packages/starlette/middleware/exceptions.py\", line 79, in __call__\n    raise exc\n  File \"/Users/topiputih/Developments/company/sii/distributed-cracking/venv/lib/python3.11/site-packages/starlette/middleware/exceptions.py\", line 68, in __call__\n    await self.app(scope, receive, sender)\n  File \"/Users/topiputih/Developments/company/sii/distributed-cracking/venv/lib/python3.11/site-packages/fastapi/middleware/asyncexitstack.py\", line 20, in __call__\n    raise e\n  File \"/Users/topiputih/Developments/company/sii/distributed-cracking/venv/lib/python3.11/site-packages/fastapi/middleware/asyncexitstack.py\", line 17, in __call__\n    await self.app(scope, receive, send)\n  File \"/Users/topiputih/Developments/company/sii/distributed-cracking/venv/lib/python3.11/site-packages/starlette/routing.py\", line 718, in __call__\n    await route.handle(scope, receive, send)\n  File \"/Users/topiputih/Developments/company/sii/distributed-cracking/venv/lib/python3.11/site-packages/starlette/routing.py\", line 276, in handle\n    await self.app(scope, receive, send)\n  File \"/Users/topiputih/Developments/company/sii/distributed-cracking/venv/lib/python3.11/site-packages/starlette/routing.py\", line 66, in app\n    response = await func(request)\n               ^^^^^^^^^^^^^^^^^^^\n  File \"/Users/topiputih/Developments/company/sii/distributed-cracking/venv/lib/python3.11/site-packages/fastapi/routing.py\", line 274, in app\n    raw_response = await run_endpoint_function(\n                   ^^^^^^^^^^^^^^^^^^^^^^^^^^^^\n  File \"/Users/topiputih/Developments/company/sii/distributed-cracking/venv/lib/python3.11/site-packages/fastapi/routing.py\", line 191, in run_endpoint_function\n    return await dependant.call(**values)\n           ^^^^^^^^^^^^^^^^^^^^^^^^^^^^^^\n  File \"/Users/topiputih/Developments/company/sii/distributed-cracking/_cmd_temp/server.py\", line 337, in get_tasks\n    tasks = await task_usecase.get_all_tasks(pagination.skip, pagination.limit)\n            ^^^^^^^^^^^^^^^^^^^^^^^^^^^^^^^^^^^^^^^^^^^^^^^^^^^^^^^^^^^^^^^^^^^\n  File \"/Users/topiputih/Developments/company/sii/distributed-cracking/usecase/task_usecase.py\", line 58, in get_all_tasks\n    return await self.task_repo.find_all(skip, limit)\n           ^^^^^^^^^^^^^^^^^^^^^^^^^^^^^^^^^^^^^^^^^^\n  File \"/Users/topiputih/Developments/company/sii/distributed-cracking/repository/task_repository.py\", line 72, in find_all\n    cursor = self.collection.find().skip(skip).limit(limit)\n             ^^^^^^^^^^^^^^^^^^^^^^^^^^^\nAttributeError: 'coroutine' object has no attribute 'skip'\n"}
{"timestamp": "2025-06-03T18:23:12.179787", "level": "ERROR", "logger": "server", "message": "Error retrieving tasks: 'async_generator' object is not iterable", "module": "logging_config", "function": "log_with_context", "line": 119, "error_type": "TypeError", "traceback": "Traceback (most recent call last):\n  File \"/Users/topiputih/Developments/company/sii/distributed-cracking/_cmd_temp/server.py\", line 337, in get_tasks\n    tasks = await task_usecase.get_all_tasks(pagination.skip, pagination.limit)\n            ^^^^^^^^^^^^^^^^^^^^^^^^^^^^^^^^^^^^^^^^^^^^^^^^^^^^^^^^^^^^^^^^^^^\n  File \"/Users/topiputih/Developments/company/sii/distributed-cracking/usecase/task_usecase.py\", line 58, in get_all_tasks\n    return await self.task_repo.find_all(skip, limit)\n           ^^^^^^^^^^^^^^^^^^^^^^^^^^^^^^^^^^^^^^^^^^\n  File \"/Users/topiputih/Developments/company/sii/distributed-cracking/repository/task_repository.py\", line 74, in find_all\n    async for task_dict in cursor:\n  File \"/Library/Frameworks/Python.framework/Versions/3.11/lib/python3.11/unittest/mock.py\", line 1108, in __call__\n    return self._mock_call(*args, **kwargs)\n           ^^^^^^^^^^^^^^^^^^^^^^^^^^^^^^^^\n  File \"/Library/Frameworks/Python.framework/Versions/3.11/lib/python3.11/unittest/mock.py\", line 1112, in _mock_call\n    return self._execute_mock_call(*args, **kwargs)\n           ^^^^^^^^^^^^^^^^^^^^^^^^^^^^^^^^^^^^^^^^\n  File \"/Library/Frameworks/Python.framework/Versions/3.11/lib/python3.11/unittest/mock.py\", line 1173, in _execute_mock_call\n    result = effect(*args, **kwargs)\n             ^^^^^^^^^^^^^^^^^^^^^^^\n  File \"/Library/Frameworks/Python.framework/Versions/3.11/lib/python3.11/unittest/mock.py\", line 2039, in __aiter__\n    return _AsyncIterator(iter(ret_val))\n                          ^^^^^^^^^^^^^\nTypeError: 'async_generator' object is not iterable\n"}
{"timestamp": "2025-06-03T18:23:12.183758", "level": "ERROR", "logger": "server", "message": "Unhandled exception: TypeError: 'async_generator' object is not iterable", "module": "logging_config", "function": "log_with_context", "line": 119, "error_id": "4428079232", "error_type": "TypeError", "path": "/tasks", "method": "GET", "client": "testclient", "traceback": "Traceback (most recent call last):\n  File \"/Users/topiputih/Developments/company/sii/distributed-cracking/venv/lib/python3.11/site-packages/starlette/middleware/errors.py\", line 162, in __call__\n    await self.app(scope, receive, _send)\n  File \"/Users/topiputih/Developments/company/sii/distributed-cracking/venv/lib/python3.11/site-packages/starlette/middleware/cors.py\", line 83, in __call__\n    await self.app(scope, receive, send)\n  File \"/Users/topiputih/Developments/company/sii/distributed-cracking/venv/lib/python3.11/site-packages/starlette/middleware/exceptions.py\", line 79, in __call__\n    raise exc\n  File \"/Users/topiputih/Developments/company/sii/distributed-cracking/venv/lib/python3.11/site-packages/starlette/middleware/exceptions.py\", line 68, in __call__\n    await self.app(scope, receive, sender)\n  File \"/Users/topiputih/Developments/company/sii/distributed-cracking/venv/lib/python3.11/site-packages/fastapi/middleware/asyncexitstack.py\", line 20, in __call__\n    raise e\n  File \"/Users/topiputih/Developments/company/sii/distributed-cracking/venv/lib/python3.11/site-packages/fastapi/middleware/asyncexitstack.py\", line 17, in __call__\n    await self.app(scope, receive, send)\n  File \"/Users/topiputih/Developments/company/sii/distributed-cracking/venv/lib/python3.11/site-packages/starlette/routing.py\", line 718, in __call__\n    await route.handle(scope, receive, send)\n  File \"/Users/topiputih/Developments/company/sii/distributed-cracking/venv/lib/python3.11/site-packages/starlette/routing.py\", line 276, in handle\n    await self.app(scope, receive, send)\n  File \"/Users/topiputih/Developments/company/sii/distributed-cracking/venv/lib/python3.11/site-packages/starlette/routing.py\", line 66, in app\n    response = await func(request)\n               ^^^^^^^^^^^^^^^^^^^\n  File \"/Users/topiputih/Developments/company/sii/distributed-cracking/venv/lib/python3.11/site-packages/fastapi/routing.py\", line 274, in app\n    raw_response = await run_endpoint_function(\n                   ^^^^^^^^^^^^^^^^^^^^^^^^^^^^\n  File \"/Users/topiputih/Developments/company/sii/distributed-cracking/venv/lib/python3.11/site-packages/fastapi/routing.py\", line 191, in run_endpoint_function\n    return await dependant.call(**values)\n           ^^^^^^^^^^^^^^^^^^^^^^^^^^^^^^\n  File \"/Users/topiputih/Developments/company/sii/distributed-cracking/_cmd_temp/server.py\", line 337, in get_tasks\n    tasks = await task_usecase.get_all_tasks(pagination.skip, pagination.limit)\n            ^^^^^^^^^^^^^^^^^^^^^^^^^^^^^^^^^^^^^^^^^^^^^^^^^^^^^^^^^^^^^^^^^^^\n  File \"/Users/topiputih/Developments/company/sii/distributed-cracking/usecase/task_usecase.py\", line 58, in get_all_tasks\n    return await self.task_repo.find_all(skip, limit)\n           ^^^^^^^^^^^^^^^^^^^^^^^^^^^^^^^^^^^^^^^^^^\n  File \"/Users/topiputih/Developments/company/sii/distributed-cracking/repository/task_repository.py\", line 74, in find_all\n    async for task_dict in cursor:\n  File \"/Library/Frameworks/Python.framework/Versions/3.11/lib/python3.11/unittest/mock.py\", line 1108, in __call__\n    return self._mock_call(*args, **kwargs)\n           ^^^^^^^^^^^^^^^^^^^^^^^^^^^^^^^^\n  File \"/Library/Frameworks/Python.framework/Versions/3.11/lib/python3.11/unittest/mock.py\", line 1112, in _mock_call\n    return self._execute_mock_call(*args, **kwargs)\n           ^^^^^^^^^^^^^^^^^^^^^^^^^^^^^^^^^^^^^^^^\n  File \"/Library/Frameworks/Python.framework/Versions/3.11/lib/python3.11/unittest/mock.py\", line 1173, in _execute_mock_call\n    result = effect(*args, **kwargs)\n             ^^^^^^^^^^^^^^^^^^^^^^^\n  File \"/Library/Frameworks/Python.framework/Versions/3.11/lib/python3.11/unittest/mock.py\", line 2039, in __aiter__\n    return _AsyncIterator(iter(ret_val))\n                          ^^^^^^^^^^^^^\nTypeError: 'async_generator' object is not iterable\n"}
{"timestamp": "2025-06-03T18:24:18.409201", "level": "ERROR", "logger": "server", "message": "Error retrieving tasks: 'AsyncItemIterator' object is not iterable", "module": "logging_config", "function": "log_with_context", "line": 119, "error_type": "TypeError", "traceback": "Traceback (most recent call last):\n  File \"/Users/topiputih/Developments/company/sii/distributed-cracking/_cmd_temp/server.py\", line 337, in get_tasks\n    tasks = await task_usecase.get_all_tasks(pagination.skip, pagination.limit)\n            ^^^^^^^^^^^^^^^^^^^^^^^^^^^^^^^^^^^^^^^^^^^^^^^^^^^^^^^^^^^^^^^^^^^\n  File \"/Users/topiputih/Developments/company/sii/distributed-cracking/usecase/task_usecase.py\", line 58, in get_all_tasks\n    return await self.task_repo.find_all(skip, limit)\n           ^^^^^^^^^^^^^^^^^^^^^^^^^^^^^^^^^^^^^^^^^^\n  File \"/Users/topiputih/Developments/company/sii/distributed-cracking/repository/task_repository.py\", line 74, in find_all\n    async for task_dict in cursor:\n  File \"/Library/Frameworks/Python.framework/Versions/3.11/lib/python3.11/unittest/mock.py\", line 1108, in __call__\n    return self._mock_call(*args, **kwargs)\n           ^^^^^^^^^^^^^^^^^^^^^^^^^^^^^^^^\n  File \"/Library/Frameworks/Python.framework/Versions/3.11/lib/python3.11/unittest/mock.py\", line 1112, in _mock_call\n    return self._execute_mock_call(*args, **kwargs)\n           ^^^^^^^^^^^^^^^^^^^^^^^^^^^^^^^^^^^^^^^^\n  File \"/Library/Frameworks/Python.framework/Versions/3.11/lib/python3.11/unittest/mock.py\", line 1173, in _execute_mock_call\n    result = effect(*args, **kwargs)\n             ^^^^^^^^^^^^^^^^^^^^^^^\n  File \"/Library/Frameworks/Python.framework/Versions/3.11/lib/python3.11/unittest/mock.py\", line 2039, in __aiter__\n    return _AsyncIterator(iter(ret_val))\n                          ^^^^^^^^^^^^^\nTypeError: 'AsyncItemIterator' object is not iterable\n"}
{"timestamp": "2025-06-03T18:24:18.412230", "level": "ERROR", "logger": "server", "message": "Unhandled exception: TypeError: 'AsyncItemIterator' object is not iterable", "module": "logging_config", "function": "log_with_context", "line": 119, "error_id": "4595852832", "error_type": "TypeError", "path": "/tasks", "method": "GET", "client": "testclient", "traceback": "Traceback (most recent call last):\n  File \"/Users/topiputih/Developments/company/sii/distributed-cracking/venv/lib/python3.11/site-packages/starlette/middleware/errors.py\", line 162, in __call__\n    await self.app(scope, receive, _send)\n  File \"/Users/topiputih/Developments/company/sii/distributed-cracking/venv/lib/python3.11/site-packages/starlette/middleware/cors.py\", line 83, in __call__\n    await self.app(scope, receive, send)\n  File \"/Users/topiputih/Developments/company/sii/distributed-cracking/venv/lib/python3.11/site-packages/starlette/middleware/exceptions.py\", line 79, in __call__\n    raise exc\n  File \"/Users/topiputih/Developments/company/sii/distributed-cracking/venv/lib/python3.11/site-packages/starlette/middleware/exceptions.py\", line 68, in __call__\n    await self.app(scope, receive, sender)\n  File \"/Users/topiputih/Developments/company/sii/distributed-cracking/venv/lib/python3.11/site-packages/fastapi/middleware/asyncexitstack.py\", line 20, in __call__\n    raise e\n  File \"/Users/topiputih/Developments/company/sii/distributed-cracking/venv/lib/python3.11/site-packages/fastapi/middleware/asyncexitstack.py\", line 17, in __call__\n    await self.app(scope, receive, send)\n  File \"/Users/topiputih/Developments/company/sii/distributed-cracking/venv/lib/python3.11/site-packages/starlette/routing.py\", line 718, in __call__\n    await route.handle(scope, receive, send)\n  File \"/Users/topiputih/Developments/company/sii/distributed-cracking/venv/lib/python3.11/site-packages/starlette/routing.py\", line 276, in handle\n    await self.app(scope, receive, send)\n  File \"/Users/topiputih/Developments/company/sii/distributed-cracking/venv/lib/python3.11/site-packages/starlette/routing.py\", line 66, in app\n    response = await func(request)\n               ^^^^^^^^^^^^^^^^^^^\n  File \"/Users/topiputih/Developments/company/sii/distributed-cracking/venv/lib/python3.11/site-packages/fastapi/routing.py\", line 274, in app\n    raw_response = await run_endpoint_function(\n                   ^^^^^^^^^^^^^^^^^^^^^^^^^^^^\n  File \"/Users/topiputih/Developments/company/sii/distributed-cracking/venv/lib/python3.11/site-packages/fastapi/routing.py\", line 191, in run_endpoint_function\n    return await dependant.call(**values)\n           ^^^^^^^^^^^^^^^^^^^^^^^^^^^^^^\n  File \"/Users/topiputih/Developments/company/sii/distributed-cracking/_cmd_temp/server.py\", line 337, in get_tasks\n    tasks = await task_usecase.get_all_tasks(pagination.skip, pagination.limit)\n            ^^^^^^^^^^^^^^^^^^^^^^^^^^^^^^^^^^^^^^^^^^^^^^^^^^^^^^^^^^^^^^^^^^^\n  File \"/Users/topiputih/Developments/company/sii/distributed-cracking/usecase/task_usecase.py\", line 58, in get_all_tasks\n    return await self.task_repo.find_all(skip, limit)\n           ^^^^^^^^^^^^^^^^^^^^^^^^^^^^^^^^^^^^^^^^^^\n  File \"/Users/topiputih/Developments/company/sii/distributed-cracking/repository/task_repository.py\", line 74, in find_all\n    async for task_dict in cursor:\n  File \"/Library/Frameworks/Python.framework/Versions/3.11/lib/python3.11/unittest/mock.py\", line 1108, in __call__\n    return self._mock_call(*args, **kwargs)\n           ^^^^^^^^^^^^^^^^^^^^^^^^^^^^^^^^\n  File \"/Library/Frameworks/Python.framework/Versions/3.11/lib/python3.11/unittest/mock.py\", line 1112, in _mock_call\n    return self._execute_mock_call(*args, **kwargs)\n           ^^^^^^^^^^^^^^^^^^^^^^^^^^^^^^^^^^^^^^^^\n  File \"/Library/Frameworks/Python.framework/Versions/3.11/lib/python3.11/unittest/mock.py\", line 1173, in _execute_mock_call\n    result = effect(*args, **kwargs)\n             ^^^^^^^^^^^^^^^^^^^^^^^\n  File \"/Library/Frameworks/Python.framework/Versions/3.11/lib/python3.11/unittest/mock.py\", line 2039, in __aiter__\n    return _AsyncIterator(iter(ret_val))\n                          ^^^^^^^^^^^^^\nTypeError: 'AsyncItemIterator' object is not iterable\n"}
{"timestamp": "2025-06-03T18:30:13.931356", "level": "ERROR", "logger": "server", "message": "Unhandled exception: ConnectionError: Database not connected. Call connect() first.", "module": "logging_config", "function": "log_with_context", "line": 119, "error_id": "4417132224", "error_type": "ConnectionError", "path": "/agents", "method": "POST", "client": "testclient", "traceback": "Traceback (most recent call last):\n  File \"/Users/topiputih/Developments/company/sii/distributed-cracking/venv/lib/python3.11/site-packages/starlette/middleware/errors.py\", line 162, in __call__\n    await self.app(scope, receive, _send)\n  File \"/Users/topiputih/Developments/company/sii/distributed-cracking/venv/lib/python3.11/site-packages/starlette/middleware/cors.py\", line 83, in __call__\n    await self.app(scope, receive, send)\n  File \"/Users/topiputih/Developments/company/sii/distributed-cracking/venv/lib/python3.11/site-packages/starlette/middleware/exceptions.py\", line 79, in __call__\n    raise exc\n  File \"/Users/topiputih/Developments/company/sii/distributed-cracking/venv/lib/python3.11/site-packages/starlette/middleware/exceptions.py\", line 68, in __call__\n    await self.app(scope, receive, sender)\n  File \"/Users/topiputih/Developments/company/sii/distributed-cracking/venv/lib/python3.11/site-packages/fastapi/middleware/asyncexitstack.py\", line 20, in __call__\n    raise e\n  File \"/Users/topiputih/Developments/company/sii/distributed-cracking/venv/lib/python3.11/site-packages/fastapi/middleware/asyncexitstack.py\", line 17, in __call__\n    await self.app(scope, receive, send)\n  File \"/Users/topiputih/Developments/company/sii/distributed-cracking/venv/lib/python3.11/site-packages/starlette/routing.py\", line 718, in __call__\n    await route.handle(scope, receive, send)\n  File \"/Users/topiputih/Developments/company/sii/distributed-cracking/venv/lib/python3.11/site-packages/starlette/routing.py\", line 276, in handle\n    await self.app(scope, receive, send)\n  File \"/Users/topiputih/Developments/company/sii/distributed-cracking/venv/lib/python3.11/site-packages/starlette/routing.py\", line 66, in app\n    response = await func(request)\n               ^^^^^^^^^^^^^^^^^^^\n  File \"/Users/topiputih/Developments/company/sii/distributed-cracking/venv/lib/python3.11/site-packages/fastapi/routing.py\", line 264, in app\n    solved_result = await solve_dependencies(\n                    ^^^^^^^^^^^^^^^^^^^^^^^^^\n  File \"/Users/topiputih/Developments/company/sii/distributed-cracking/venv/lib/python3.11/site-packages/fastapi/dependencies/utils.py\", line 563, in solve_dependencies\n    solved_result = await solve_dependencies(\n                    ^^^^^^^^^^^^^^^^^^^^^^^^^\n  File \"/Users/topiputih/Developments/company/sii/distributed-cracking/venv/lib/python3.11/site-packages/fastapi/dependencies/utils.py\", line 563, in solve_dependencies\n    solved_result = await solve_dependencies(\n                    ^^^^^^^^^^^^^^^^^^^^^^^^^\n  File \"/Users/topiputih/Developments/company/sii/distributed-cracking/venv/lib/python3.11/site-packages/fastapi/dependencies/utils.py\", line 592, in solve_dependencies\n    solved = await call(**sub_values)\n             ^^^^^^^^^^^^^^^^^^^^^^^^\n  File \"/Users/topiputih/Developments/company/sii/distributed-cracking/_cmd_temp/server.py\", line 139, in get_db\n    db = Database.get_database()\n         ^^^^^^^^^^^^^^^^^^^^^^^\n  File \"/Users/topiputih/Developments/company/sii/distributed-cracking/config/database.py\", line 38, in get_database\n    raise ConnectionError(\"Database not connected. Call connect() first.\")\nConnectionError: Database not connected. Call connect() first.\n"}
{"timestamp": "2025-06-03T18:31:19.636051", "level": "ERROR", "logger": "server", "message": "Unhandled exception: ConnectionError: Database not connected. Call connect() first.", "module": "logging_config", "function": "log_with_context", "line": 119, "error_id": "4427617984", "error_type": "ConnectionError", "path": "/agents", "method": "POST", "client": "testclient", "traceback": "Traceback (most recent call last):\n  File \"/Users/topiputih/Developments/company/sii/distributed-cracking/venv/lib/python3.11/site-packages/starlette/middleware/errors.py\", line 162, in __call__\n    await self.app(scope, receive, _send)\n  File \"/Users/topiputih/Developments/company/sii/distributed-cracking/venv/lib/python3.11/site-packages/starlette/middleware/cors.py\", line 83, in __call__\n    await self.app(scope, receive, send)\n  File \"/Users/topiputih/Developments/company/sii/distributed-cracking/venv/lib/python3.11/site-packages/starlette/middleware/exceptions.py\", line 79, in __call__\n    raise exc\n  File \"/Users/topiputih/Developments/company/sii/distributed-cracking/venv/lib/python3.11/site-packages/starlette/middleware/exceptions.py\", line 68, in __call__\n    await self.app(scope, receive, sender)\n  File \"/Users/topiputih/Developments/company/sii/distributed-cracking/venv/lib/python3.11/site-packages/fastapi/middleware/asyncexitstack.py\", line 20, in __call__\n    raise e\n  File \"/Users/topiputih/Developments/company/sii/distributed-cracking/venv/lib/python3.11/site-packages/fastapi/middleware/asyncexitstack.py\", line 17, in __call__\n    await self.app(scope, receive, send)\n  File \"/Users/topiputih/Developments/company/sii/distributed-cracking/venv/lib/python3.11/site-packages/starlette/routing.py\", line 718, in __call__\n    await route.handle(scope, receive, send)\n  File \"/Users/topiputih/Developments/company/sii/distributed-cracking/venv/lib/python3.11/site-packages/starlette/routing.py\", line 276, in handle\n    await self.app(scope, receive, send)\n  File \"/Users/topiputih/Developments/company/sii/distributed-cracking/venv/lib/python3.11/site-packages/starlette/routing.py\", line 66, in app\n    response = await func(request)\n               ^^^^^^^^^^^^^^^^^^^\n  File \"/Users/topiputih/Developments/company/sii/distributed-cracking/venv/lib/python3.11/site-packages/fastapi/routing.py\", line 264, in app\n    solved_result = await solve_dependencies(\n                    ^^^^^^^^^^^^^^^^^^^^^^^^^\n  File \"/Users/topiputih/Developments/company/sii/distributed-cracking/venv/lib/python3.11/site-packages/fastapi/dependencies/utils.py\", line 563, in solve_dependencies\n    solved_result = await solve_dependencies(\n                    ^^^^^^^^^^^^^^^^^^^^^^^^^\n  File \"/Users/topiputih/Developments/company/sii/distributed-cracking/venv/lib/python3.11/site-packages/fastapi/dependencies/utils.py\", line 563, in solve_dependencies\n    solved_result = await solve_dependencies(\n                    ^^^^^^^^^^^^^^^^^^^^^^^^^\n  File \"/Users/topiputih/Developments/company/sii/distributed-cracking/venv/lib/python3.11/site-packages/fastapi/dependencies/utils.py\", line 592, in solve_dependencies\n    solved = await call(**sub_values)\n             ^^^^^^^^^^^^^^^^^^^^^^^^\n  File \"/Users/topiputih/Developments/company/sii/distributed-cracking/_cmd_temp/server.py\", line 139, in get_db\n    db = Database.get_database()\n         ^^^^^^^^^^^^^^^^^^^^^^^\n  File \"/Users/topiputih/Developments/company/sii/distributed-cracking/config/database.py\", line 38, in get_database\n    raise ConnectionError(\"Database not connected. Call connect() first.\")\nConnectionError: Database not connected. Call connect() first.\n"}
